//console.log(c+d);
//console.log("this line is never reached");
//throw new ReferenceError()
/*try{
    console.log(a+b);
}
catch(err){
    //console.log(err)
    console.log("there was an error");
    console.log("the error was saved in error log");
}
console.log("my program doesnot stop"); */



/*try{
    throw new ReferenceError();
}
catch(err){
    console.log(err)
    console.log("There was a refernce error");
}
console.log("my program doesnot stop");*/